Workbook

Sheet Cover Page
B2: JINDAL FERROUS LIMITED — DEBT MONITORING MODEL
B3: CREDIT COMMITTEE SUMMARY
B4: ="As of: "&TEXT('Instructions & Assumptions'!B5,"DD-MMM-YYYY") -> As of: 12-May-2026
B6: 1. PROJECT OVERVIEW
B7: Project | C7: 2.0 MTPA Greenfield Integrated Steel Plant, Kalinga Nagar, Odisha | E7: Sector | F7: Iron & Steel (Ferrochrome)
B8: Borrower | C8: Jindal Ferrous Limited (JFL) | E8: Group | F8: Jindal Stainless / Ratan Jindal Group
B9: Total Proj Cost | C9: ₹4,083.94 Cr | Debt ₹2,721.43 Cr | Equity ₹1,362.51 Cr | E9: D:E Ratio | F9: 66.64 : 33.36
B10: Sanctioned Debt | C10: ₹4,666 Cr | 9 Lenders | 44 Facilities | E10: Adj Consortium | F10: ₹3,826 Cr (nets out ICICI TL ₹840 Cr takeover)
B12: 2. KEY FINANCIAL METRICS (TEV FY29 — First Covenant Test Year)
B13: Metric | C13: Value | E13: Metric | F13: Value
B14: Revenue | C14: ₹7,541 Cr | E14: Project IRR | F14: 0.1506
B15: EBITDA | C15: ₹957 Cr | E15: WACC (model) | F15: 11.2% (TEV: 10.55%)
B16: EBITDA Margin | C16: 0.127 | E16: NPV | F16: ₹1,134 Cr
B17: PAT | C17: ₹347 Cr | E17: Payback Period | F17: 5.80 years
B18: Min DSCR | C18: 1.5505x (FY30) | E18: Avg DSCR | F18: 1.9211x
B19: ISCR (FY29) | C19: 3.6549x | E19: FACR (FY29) | F19: 1.5100x
B21: 3. COVENANT SUMMARY
B22: =COUNTIF('FY29 Covenant Compliance (TEV)'!G7:G52,"Compliant*")&" / 44 Compliant (FY29 TEV Projections) | "&COUNTIF('FY29 Covenant Compliance (TEV)'!G7:G52,"Near Breach")&" Near Breach (ICICI WC Rating — at threshold)" -> 43 / 44 Compliant (FY29 TEV Projections) | 1 Near Breach (ICICI WC Rating — at threshold)
B23: First formal covenant test year: FY29 post-COD. All 43 of 44 covenants project COMPLIANT on TEV FY29 projections; 1 Near Breach (ICICI WC Rating).
B25: 4. OPEN FLAGS REQUIRING MANAGEMENT ACTION (4 High Severity)
B26: ⚠ F-01: ICICI BG limit ambiguity | C26: Annexure I states ₹300 Cr; pp.7-8 detail suggests different amount. ACTION: confirm with ICICI treasury.
B27: ⚠ F-02: RBL bridge refinance risk | C27: ₹200 Cr bullet matures 13-Nov-2026. Refinancing plan not yet confirmed. ACTION: initiate rollover negotiations.
B28: ⚠ F-07: HSBC uncommitted status | C28: ₹1,000 Cr is NOT committed — bank can cancel at discretion. ACTION: treat as contingent, not available liquidity.
B29: ⚠ F-15: HDFC FMV cover source | C29: JSL FMV / Total Debt ≥ 2.5x in offer letter not confirmed. ACTION: obtain Treasury verification of FMV data source.
B30: See Management Flags sheet for all 18 flags — 13 Open (4 High / 7 Medium / 2 Low) | 2 Closed | 2 Acceptable | 1 Open-Linked
B32: 5. MODEL INTEGRITY
B33: ='Validation & Integrity'!B118 -> 108
B34: Sources: 9 JFL sanction letters + TEV Financial Model (Sep-2025) + Statutory Audit (N.C. Aggarwal & Co., 28-Aug-2025, UDIN: 25086622BMIBYO3693)

Sheet Dashboard
A1: JINDAL FERROUS LIMITED — DEBT MONITORING DASHBOARD
A2: ="As of "&TEXT('Instructions & Assumptions'!B5,"DD-MMM-YYYY")&" | 9 Lenders | 44 Facilities | Source: JFL sanction letters + TEV Financial Model + Statutory Audit" -> As of 12-May-2026 | 9 Lenders | 44 Facilities | Source: JFL sanction letters + TEV Financial Model + Statutory Audit
A3: ="MODEL INTEGRITY: "&'Validation & Integrity'!B118 -> MODEL INTEGRITY: 108
A4: A. SANCTIONED DEBT OVERVIEW
B5: A. SANCTIONED DEBT OVERVIEW
B6: SANCTIONED DEBT (₹ Cr) | E6: FB MAINS (₹ Cr) | H6: NFB MAINS (₹ Cr) | K6: NFB CONTINGENT (₹ Cr) | N6: ADJ CONSORTIUM (₹ Cr)
B7: ='Lender Summary'!B20 -> 4666 | E7: ='Lender Summary'!B21 -> 4116 | H7: ='Lender Summary'!B22 -> 550 | K7: ='Lender Summary'!B23 -> 2040 | N7: =AdjustedConsortiumDebt -> 3826
B8: FD-BACKED (₹ Cr) | E8: UNCOMMITTED MEMO (₹ Cr) | H8: HEDGE MEMO (₹ Cr) | K8: WAC OF FB DEBT | N8: ANNUAL RUN-RATE INTEREST (₹ Cr)
B9: ='Lender Summary'!B24 -> 150 | E9: ='Lender Summary'!B25 -> 0 | H9: ='Lender Summary'!B26 -> 75 | K9: ='Interest Schedule'!C59 -> 0.091499271 | N9: =TotalIntComm -> 393.161
B10: ACTIVE FACILITIES | E10: COVENANTS (FY29 TEV) | H10: AVG UTILIZATION | K10: TOTAL TL PRINCIPAL O/S (₹ Cr) | N10: ICICI TL TAKEOVER (₹ Cr)
B11: =COUNTA('Facility Master'!A5:A48) -> 44 | E11: =COUNTIF('FY29 Covenant Compliance (TEV)'!G7:G52,"Compliant*")&" / "&COUNTA('FY29 Covenant Compliance (TEV)'!B7:B52)&" Compliant (FY29)" -> 43 / 44 Compliant (FY29) | H11: =AVERAGEIFS('Facility Master'!N5:N48,'Facility Master'!H5:H48,">0") -> 1 | K11: =Total_TL_PrincOS -> 3816 | N11: =ICICI_TL_Takeover -> 840
B12: =COUNTIF('FY29 Covenant Compliance (TEV)'!G7:G52,"Compliant*")&" / 44 Compliant (FY29 TEV — First Covenant Test Year) | "&COUNTIF('FY29 Covenant Compliance (TEV)'!G7:G52,"Near Breach")&" Near Breach" -> 43 / 44 Compliant (FY29 TEV — First Covenant Test Year) | 1 Near Breach
B14: B. COVENANT COMPLIANCE — FY29 TEV PROJECTIONS (First Post-COD Test Year)
B15: TOTAL COVENANTS | F15: COMPLIANT (FY29) | J15: NEAR BREACH | M15: BREACHED
B16: =COUNTA('FY29 Covenant Compliance (TEV)'!B7:B52) -> 44 | F16: =COUNTIF('FY29 Covenant Compliance (TEV)'!G7:G52,"Compliant*") -> 43 | J16: =COUNTIF('FY29 Covenant Compliance (TEV)'!G7:G52,"Near Breach") -> 1 | M16: =COUNTIF('FY29 Covenant Compliance (TEV)'!G7:G52,"Breached") -> 0
B17: Source: FY29 Covenant Compliance (TEV) sheet — first formal test year for consortium covenants.
B18: C. LENDER CONCENTRATION (Sanctioned Debt = B1 + B2, ₹ Cr)
B19: Lender | E19: Sanctioned (₹ Cr) | G19: % Share | H19: Concentration Bar (normalised to UBI) | N19: NFB Contingent (₹ Cr) | O19: ='Lender Summary'!G7 -> 0
B20: UBI | E20: ='Lender Summary'!D6 -> 1361 | G20: ='Lender Summary'!E6 -> 0.29168453 | H20: =REPT("█",ROUND(G20*100,0)) -> █████████████████████████████ | N20: ='Lender Summary'!G6 -> 750 | O20: ='Lender Summary'!G8 -> 200
B21: Indian Bank | E21: ='Lender Summary'!D7 -> 235 | G21: ='Lender Summary'!E7 -> 0.050364338 | H21: =REPT("█",ROUND(G21*100,0)) -> █████ | N21: ='Lender Summary'!G7 -> 0 | O21: ='Lender Summary'!G9 -> 100
B22: RBL Bank | E22: ='Lender Summary'!D8 -> 200 | G22: ='Lender Summary'!E8 -> 0.042863266 | H22: =REPT("█",ROUND(G22*100,0)) -> ████ | N22: ='Lender Summary'!G8 -> 200 | O22: ='Lender Summary'!G10 -> 400
B23: YES Bank | E23: ='Lender Summary'!D9 -> 650 | G23: ='Lender Summary'!E9 -> 0.13930562 | H23: =REPT("█",ROUND(G23*100,0)) -> ██████████████ | N23: ='Lender Summary'!G9 -> 100 | O23: ='Lender Summary'!G11 -> 300
B24: IDFC First Bank | E24: ='Lender Summary'!D10 -> 530 | G24: ='Lender Summary'!E10 -> 0.11358766 | H24: =REPT("█",ROUND(G24*100,0)) -> ███████████ | N24: ='Lender Summary'!G10 -> 400 | O24: ='Lender Summary'!G12 -> 0
B25: ICICI Bank WC | E25: ='Lender Summary'!D11 -> 400 | G25: ='Lender Summary'!E11 -> 0.085726532 | H25: =REPT("█",ROUND(G25*100,0)) -> █████████ | N25: ='Lender Summary'!G11 -> 300 | O25: ='Lender Summary'!G13 -> 250
B26: HSBC (₹200 Cr post-haircut, B1 — see MP-13/F-18) | E26: ='Lender Summary'!D12 -> 200 | G26: ='Lender Summary'!E12 -> 0.042863266 | H26: =REPT("█",ROUND(G26*100,0)) -> ████ | N26: ='Lender Summary'!G12 -> 0 | O26: ='Lender Summary'!G14 -> 40
B27: HDFC Bank | E27: ='Lender Summary'!D13 -> 250 | G27: ='Lender Summary'!E13 -> 0.053579083 | H27: =REPT("█",ROUND(G27*100,0)) -> █████ | N27: ='Lender Summary'!G13 -> 250 | O27: =SUM(O18:O26) -> 1290
B28: ICICI Bank (TL) | E28: ='Lender Summary'!D14 -> 840 | G28: ='Lender Summary'!E14 -> 0.18002572 | H28: =REPT("█",ROUND(G28*100,0)) -> ██████████████████ | N28: ='Lender Summary'!G14 -> 40
B29: Grand Total | E29: =SUM(E20:E28) -> 4666 | G29: =SUM(G20:G28) -> 1 | N29: =SUM(N20:N28) -> 2040
B30: D. TERM LOAN MATURITY PROFILE (Principal Repayment by Fiscal Year, ₹ Cr) — excl. RBL Bridge ₹200 Cr bullet (see F-02)
B31: Fiscal Year | D31: Principal (₹ Cr) | G31: Repayment Profile Bar
B32: FY24 | D32: =SUMIFS('Repayment Schedule'!AM5:AM68,'Repayment Schedule'!B5:B68,">="&DATE(2023,4,1),'Repayment Schedule'!B5:B68,"<="&DATE(2024,3,31)) -> 0 | G32: =IFERROR(REPT("█",ROUND(D32/40,0)),"")
B33: FY25 | D33: =SUMIFS('Repayment Schedule'!AM5:AM68,'Repayment Schedule'!B5:B68,">="&DATE(2024,4,1),'Repayment Schedule'!B5:B68,"<="&DATE(2025,3,31)) -> 0 | G33: =IFERROR(REPT("█",ROUND(D33/40,0)),"")
B34: FY26 | D34: =SUMIFS('Repayment Schedule'!AM5:AM68,'Repayment Schedule'!B5:B68,">="&DATE(2025,4,1),'Repayment Schedule'!B5:B68,"<="&DATE(2026,3,31)) -> 0 | G34: =IFERROR(REPT("█",ROUND(D34/40,0)),"")
B35: FY27 | D35: =SUMIFS('Repayment Schedule'!AM5:AM68,'Repayment Schedule'!B5:B68,">="&DATE(2026,4,1),'Repayment Schedule'!B5:B68,"<="&DATE(2027,3,31)) -> 2.9375 | G35: =IFERROR(REPT("█",ROUND(D35/40,0)),"")
B36: FY28 | D36: =SUMIFS('Repayment Schedule'!AM5:AM68,'Repayment Schedule'!B5:B68,">="&DATE(2027,4,1),'Repayment Schedule'!B5:B68,"<="&DATE(2028,3,31)) -> 180.8 | G36: =IFERROR(REPT("█",ROUND(D36/40,0)),"") -> █████
B37: FY29 | D37: =SUMIFS('Repayment Schedule'!AM5:AM68,'Repayment Schedule'!B5:B68,">="&DATE(2028,4,1),'Repayment Schedule'!B5:B68,"<="&DATE(2029,3,31)) -> 183.15 | G37: =IFERROR(REPT("█",ROUND(D37/40,0)),"") -> █████
B38: FY30 | D38: =SUMIFS('Repayment Schedule'!AM5:AM68,'Repayment Schedule'!B5:B68,">="&DATE(2029,4,1),'Repayment Schedule'!B5:B68,"<="&DATE(2030,3,31)) -> 325.44 | G38: =IFERROR(REPT("█",ROUND(D38/40,0)),"") -> ████████
B39: FY31 | D39: =SUMIFS('Repayment Schedule'!AM5:AM68,'Repayment Schedule'!B5:B68,">="&DATE(2030,4,1),'Repayment Schedule'!B5:B68,"<="&DATE(2031,3,31)) -> 325.44 | G39: =IFERROR(REPT("█",ROUND(D39/40,0)),"") -> ████████
B40: FY32 | D40: =SUMIFS('Repayment Schedule'!AM5:AM68,'Repayment Schedule'!B5:B68,">="&DATE(2031,4,1),'Repayment Schedule'!B5:B68,"<="&DATE(2032,3,31)) -> 325.44 | G40: =IFERROR(REPT("█",ROUND(D40/40,0)),"") -> ████████
B41: FY33 | D41: =SUMIFS('Repayment Schedule'!AM5:AM68,'Repayment Schedule'!B5:B68,">="&DATE(2032,4,1),'Repayment Schedule'!B5:B68,"<="&DATE(2033,3,31)) -> 325.44 | G41: =IFERROR(REPT("█",ROUND(D41/40,0)),"") -> ████████
...

Sheet FY29 Covenant Compliance (TEV)
A1: FY29 COVENANT COMPLIANCE — TEV-SOURCED PROJECTIONS
A2: Source: TEV Financial Model FY29 projections. Market-Practice exceptions: MP-08 (Quasi-Equity), MP-09 (JSL FMV), MP-10 (HSBC Pledge), MP-11 (IDFC DSCR). Full methodology in Notes sheet.
A3: NOTE: All 43 of 44 covenants project COMPLIANT on TEV FY29 projections (first formal test year post-COD). 1 Near Breach: ICICI WC External Rating (at threshold, not breached).
A6: # | B6: Lender | C6: Covenant | D6: Op | E6: Threshold | F6: FY29 Actual | G6: Status | H6: Headroom | L6: Source
A7: 4 | B7: UBI Consortium | C7: DSCR | D7: >= | E7: 1.25 | F7: 1.8008829 | G7: Compliant | H7: +44% | L7: TEV
A8: 5 | C8: FACR | D8: >= | E8: 1.2 | F8: 1.5100186 | G8: Compliant | H8: +26% | L8: TEV
A9: 6 | C9: ISCR | D9: >= | E9: 2 | F9: 3.6548828 | G9: Compliant | H9: +83% | L9: TEV
A10: 7 | C10: LTD/EBITDA | D10: <= | E10: 4 | F10: 2.4944117 | G10: Compliant | H10: +38% | L10: TEV
A11: 8 | C11: LTD/Equity | D11: <= | E11: 2 | F11: 1.0922542 | G11: Compliant | H11: +45% | L11: TEV
A12: 9 | B12: Indian Bank | C12: DSCR (presumed) | D12: >= | E12: 1.25 | F12: 1.8008829 | G12: Compliant | H12: +44% | L12: TEV
A13: 10 | B13: YES Bank | C13: DSCR | D13: >= | E13: 1.25 | F13: 1.8008829 | G13: Compliant | H13: +44% | L13: TEV
A14: 11 | C14: FACR | D14: >= | E14: 1.2 | F14: 1.5100186 | G14: Compliant | H14: +26% | L14: TEV
A15: 12 | C15: ISCR | D15: >= | E15: 2 | F15: 3.6548828 | G15: Compliant | H15: +83% | L15: TEV
A16: 13 | C16: LTD/EBITDA | D16: <= | E16: 4 | F16: 2.4944117 | G16: Compliant | H16: +38% | L16: TEV
A17: 14 | C17: LTD/Equity | D17: <= | E17: 2 | F17: 1.0922542 | G17: Compliant | H17: +45% | L17: TEV
A18: 15 | C18: Cash Sweep Trigger (DSCR) | D18: >= | E18: 1.5 | F18: 1.8008829 | G18: Compliant | H18: +20% | L18: TEV
A19: 16 | B19: IDFC First Bank | C19: DSCR (IDFC) | D19: >= | E19: 1.25 | F19: =('TEV Inputs'!I8 - 'TEV Inputs'!I11 - 'TEV Inputs'!I14) / ('TEV Inputs'!I40 + 'TEV Inputs'!I12) -> 2.0479877 | G19: =IFERROR(IF(D19=">=",IF(F19>=E19,IF((F19-E19)/MAX(ABS(E19),1)>0.1,"Compliant","Near Breach"),"Breached"),IF(F19<=E19,IF((E19-F19)/MAX(ABS(E19),1)>0.1,"Compliant","Near Breach"),"Breached")),"Pending") -> Compliant | H19: +64% | L19: TEV + IDFC SL p.12 (IDFC-specific DSCR formula); MP-11
A20: 17 | C20: FACR | D20: >= | E20: 1.2 | F20: 1.5100186 | G20: Compliant | H20: +26% | L20: TEV
A21: 18 | C21: ISCR | D21: >= | E21: 2 | F21: 3.6548828 | G21: Compliant | H21: +83% | L21: TEV
A22: 19 | C22: LTD/EBITDA | D22: <= | E22: 4 | F22: 2.4944117 | G22: Compliant | H22: +38% | L22: TEV
A23: 20 | C23: LTD/Equity | D23: <= | E23: 2 | F23: 1.0922542 | G23: Compliant | H23: +45% | L23: TEV
A24: 21 | C24: Quasi Equity Cap (₹ Cr) | D24: <= | E24: 337.5 | F24: 0 | G24: Compliant | H24: +100% | L24: MP-08
A25: 22 | B25: ICICI Bank (TL) | C25: DSCR | D25: >= | E25: 1.25 | F25: 1.8008829 | G25: Compliant | H25: +44% | L25: TEV
A26: 23 | C26: FACR | D26: >= | E26: 1.2 | F26: 1.5100186 | G26: Compliant | H26: +26% | L26: TEV
A27: 24 | C27: ISCR | D27: >= | E27: 2 | F27: 3.6548828 | G27: Compliant | H27: +83% | L27: TEV
A28: 25 | C28: LTD/EBITDA | D28: <= | E28: 4 | F28: 2.4944117 | G28: Compliant | H28: +38% | L28: TEV
A29: 26 | C29: LTD/Equity | D29: <= | E29: 2 | F29: 1.0922542 | G29: Compliant | H29: +45% | L29: TEV
A30: 27 | B30: RBL Bank | C30: Min Promoter Contribution (₹ Cr) | D30: >= | E30: 1363 | F30: 2186.35 | G30: Compliant | H30: +60% | L30: TEV (Equity)
A31: 28 | C31: JSL FMV Unencumbered / Total Debt | D31: >= | E31: 2.5 | F31: 11.381328 | G31: Compliant | H31: +355% | L31: MP-09 (NSE)
A32: 29 | C32: External Rating ≥ BBB | D32: >= | E32: 10 | F32: 14 | G32: Compliant | H32: +17% | L32: RBL SL p.11
A33: 30 | B33: ICICI Bank (WC) | C33: Total Debt / EBITDA | D33: <= | E33: 4 | F33: 2.8147719 | G33: Compliant | H33: +30% | L33: TEV
A34: 31 | C34: TOL / TNW | D34: <= | E34: 2.5 | F34: 1.7216136 | G34: Compliant | H34: +31% | L34: TEV
A35: 32 | C35: Current Ratio | D35: >= | E35: 1.1 | F35: 1.8878634 | G35: Compliant | H35: +72% | L35: TEV
A36: 33 | C36: External Rating ≥ A- | D36: >= | E36: 14 | F36: 14 | G36: Near Breach | H36: +0% | L36: CRISIL Jan-25
A37: 35 | B37: HDFC Bank | C37: JSL FMV / Total Debt Cover | D37: >= | E37: 2.5 | F37: 11.381328 | G37: Compliant ⚠ F-15 | H37: +355% | L37: MP-09 ⚠ F-15
A38: 36 | C38: DSCR | D38: >= | E38: 1.25 | F38: 1.8008829 | G38: Compliant | H38: +44% | L38: TEV
A39: 37 | C39: FACR | D39: >= | E39: 1.2 | F39: 1.5100186 | G39: Compliant | H39: +26% | L39: TEV
A40: 38 | C40: ISCR | D40: >= | E40: 2 | F40: 3.6548828 | G40: Compliant | H40: +83% | L40: TEV
A41: 39 | C41: LTD/EBITDA | D41: <= | E41: 4 | F41: 2.4944117 | G41: Compliant | H41: +38% | L41: TEV
A42: 40 | C42: LTD/Equity | D42: <= | E42: 2 | F42: 1.0922542 | G42: Compliant | H42: +45% | L42: TEV
...

Sheet Covenant Tracker
A1: COVENANT TRACKER — Financial Covenant Compliance
A2: Actuals from active financials (toggle FinBasis). Status: Compliant / Near Breach / Breached / Not Yet Due. 44 covenants across 9 lenders.
A3: Lender | B3: Covenant | C3: Op | D3: Threshold | E3: Actual | F3: Headroom | G3: Status | H3: Risk | I3: SL Reference | J3: Source Type | K3: Frequency | L3: First Test
A4: UBI | B4: DSCR (consortium) | C4: >= | D4: 1.25 | E4: =IFERROR(INDEX('FY29 Covenant Compliance (TEV)'!F:F,MATCH(M4,'FY29 Covenant Compliance (TEV)'!A:A,0)),"—") -> 1.8008829 | F4: =IFERROR(IF(C4=">=",E4-D4,D4-E4),"—") -> 0.55088295 | G4: =IFERROR(IF(ISTEXT(E4),"Pending Input",IF(F4<0,"Breached",IF(F4<ABS(D4)*0.05,"Near Breach","Compliant"))),"—") -> Compliant | H4: =IFERROR(IF(G4="Breached","Critical",IF(G4="Near Breach","Medium",IF(G4="Compliant","Low","—"))),"—") -> Low | I4: UBI SL 20-Sep-2025 | DSCR ≥ 1.25x | J4: SL ✓ | K4: Annual | L4: FY29 (post-COD) | M4: 4
B5: FACR (consortium) | C5: >= | D5: 1.2 | E5: =IFERROR(INDEX('FY29 Covenant Compliance (TEV)'!F:F,MATCH(M5,'FY29 Covenant Compliance (TEV)'!A:A,0)),"—") -> 1.5100186 | F5: =IFERROR(IF(C5=">=",E5-D5,D5-E5),"—") -> 0.31001863 | G5: =IFERROR(IF(ISTEXT(E5),"Pending Input",IF(F5<0,"Breached",IF(F5<ABS(D5)*0.05,"Near Breach","Compliant"))),"—") -> Compliant | H5: =IFERROR(IF(G5="Breached","Critical",IF(G5="Near Breach","Medium",IF(G5="Compliant","Low","—"))),"—") -> Low | I5: UBI SL 20-Sep-2025 | FACR ≥ 1.20x | J5: SL ✓ | K5: Annual | L5: FY29 (post-COD) | M5: 5
B6: ISCR (consortium) | C6: >= | D6: 2 | E6: =IFERROR(INDEX('FY29 Covenant Compliance (TEV)'!F:F,MATCH(M6,'FY29 Covenant Compliance (TEV)'!A:A,0)),"—") -> 3.6548828 | F6: =IFERROR(IF(C6=">=",E6-D6,D6-E6),"—") -> 1.6548828 | G6: =IFERROR(IF(ISTEXT(E6),"Pending Input",IF(F6<0,"Breached",IF(F6<ABS(D6)*0.05,"Near Breach","Compliant"))),"—") -> Compliant | H6: =IFERROR(IF(G6="Breached","Critical",IF(G6="Near Breach","Medium",IF(G6="Compliant","Low","—"))),"—") -> Low | I6: UBI SL 20-Sep-2025 | ISCR ≥ 2.00x | J6: SL ✓ | K6: Annual | L6: FY29 (post-COD) | M6: 6
B7: LTD / EBITDA (consortium) | C7: <= | D7: 4 | E7: =IFERROR(INDEX('FY29 Covenant Compliance (TEV)'!F:F,MATCH(M7,'FY29 Covenant Compliance (TEV)'!A:A,0)),"—") -> 2.4944117 | F7: =IFERROR(IF(C7=">=",E7-D7,D7-E7),"—") -> 1.5055883 | G7: =IFERROR(IF(ISTEXT(E7),"Pending Input",IF(F7<0,"Breached",IF(F7<ABS(D7)*0.05,"Near Breach","Compliant"))),"—") -> Compliant | H7: =IFERROR(IF(G7="Breached","Critical",IF(G7="Near Breach","Medium",IF(G7="Compliant","Low","—"))),"—") -> Low | I7: UBI SL 20-Sep-2025 | LTD/EBITDA ≤ 4.00x | J7: SL ✓ | K7: Annual | L7: FY29 (post-COD) | M7: 7
B8: LTD / Equity (consortium) | C8: <= | D8: 2 | E8: =IFERROR(INDEX('FY29 Covenant Compliance (TEV)'!F:F,MATCH(M8,'FY29 Covenant Compliance (TEV)'!A:A,0)),"—") -> 1.0922542 | F8: =IFERROR(IF(C8=">=",E8-D8,D8-E8),"—") -> 0.90774579 | G8: =IFERROR(IF(ISTEXT(E8),"Pending Input",IF(F8<0,"Breached",IF(F8<ABS(D8)*0.05,"Near Breach","Compliant"))),"—") -> Compliant | H8: =IFERROR(IF(G8="Breached","Critical",IF(G8="Near Breach","Medium",IF(G8="Compliant","Low","—"))),"—") -> Low | I8: UBI SL 20-Sep-2025 | LTD/Equity ≤ 2.00x | J8: SL ✓ | K8: Annual | L8: FY29 (post-COD) | M8: 8
A9: Indian Bank | B9: DSCR (consortium-presumed) | C9: >= | D9: 1.25 | E9: =IFERROR(INDEX('FY29 Covenant Compliance (TEV)'!F:F,MATCH(M9,'FY29 Covenant Compliance (TEV)'!A:A,0)),"—") -> 1.8008829 | F9: =IFERROR(IF(C9=">=",E9-D9,D9-E9),"—") -> 0.55088295 | G9: =IFERROR(IF(ISTEXT(E9),"Pending Input",IF(F9<0,"Breached",IF(F9<ABS(D9)*0.05,"Near Breach","Compliant"))),"—") -> Compliant | H9: =IFERROR(IF(G9="Breached","Critical",IF(G9="Near Breach","Medium",IF(G9="Compliant","Low","—"))),"—") -> Low | I9: Indian Bank 26-Sep-2025 (amendment only). Consortium-standard DSCR assumed — CONFIRM with Indian Bank. | J9: MP | K9: Annual | L9: FY29 (presumed) | M9: 9
A10: YES Bank | B10: DSCR (consortium) | C10: >= | D10: 1.25 | E10: =IFERROR(INDEX('FY29 Covenant Compliance (TEV)'!F:F,MATCH(M10,'FY29 Covenant Compliance (TEV)'!A:A,0)),"—") -> 1.8008829 | F10: =IFERROR(IF(C10=">=",E10-D10,D10-E10),"—") -> 0.55088295 | G10: =IFERROR(IF(ISTEXT(E10),"Pending Input",IF(F10<0,"Breached",IF(F10<ABS(D10)*0.05,"Near Breach","Compliant"))),"—") -> Compliant | H10: =IFERROR(IF(G10="Breached","Critical",IF(G10="Near Breach","Medium",IF(G10="Compliant","Low","—"))),"—") -> Low | I10: YBL SL 29-Dec-2025 | DSCR ≥ 1.25x | J10: SL ✓ | K10: Annual | L10: FY29 (post-COD) | M10: 10
B11: FACR (consortium) | C11: >= | D11: 1.2 | E11: =IFERROR(INDEX('FY29 Covenant Compliance (TEV)'!F:F,MATCH(M11,'FY29 Covenant Compliance (TEV)'!A:A,0)),"—") -> 1.5100186 | F11: =IFERROR(IF(C11=">=",E11-D11,D11-E11),"—") -> 0.31001863 | G11: =IFERROR(IF(ISTEXT(E11),"Pending Input",IF(F11<0,"Breached",IF(F11<ABS(D11)*0.05,"Near Breach","Compliant"))),"—") -> Compliant | H11: =IFERROR(IF(G11="Breached","Critical",IF(G11="Near Breach","Medium",IF(G11="Compliant","Low","—"))),"—") -> Low | I11: YBL SL 29-Dec-2025 | FACR ≥ 1.20x | J11: SL ✓ | K11: Annual | L11: FY29 (post-COD) | M11: 11
B12: ISCR (consortium) | C12: >= | D12: 2 | E12: =IFERROR(INDEX('FY29 Covenant Compliance (TEV)'!F:F,MATCH(M12,'FY29 Covenant Compliance (TEV)'!A:A,0)),"—") -> 3.6548828 | F12: =IFERROR(IF(C12=">=",E12-D12,D12-E12),"—") -> 1.6548828 | G12: =IFERROR(IF(ISTEXT(E12),"Pending Input",IF(F12<0,"Breached",IF(F12<ABS(D12)*0.05,"Near Breach","Compliant"))),"—") -> Compliant | H12: =IFERROR(IF(G12="Breached","Critical",IF(G12="Near Breach","Medium",IF(G12="Compliant","Low","—"))),"—") -> Low | I12: YBL SL 29-Dec-2025 | ISCR ≥ 2.00x | J12: SL ✓ | K12: Annual | L12: FY29 (post-COD) | M12: 12
B13: LTD / EBITDA (consortium) | C13: <= | D13: 4 | E13: =IFERROR(INDEX('FY29 Covenant Compliance (TEV)'!F:F,MATCH(M13,'FY29 Covenant Compliance (TEV)'!A:A,0)),"—") -> 2.4944117 | F13: =IFERROR(IF(C13=">=",E13-D13,D13-E13),"—") -> 1.5055883 | G13: =IFERROR(IF(ISTEXT(E13),"Pending Input",IF(F13<0,"Breached",IF(F13<ABS(D13)*0.05,"Near Breach","Compliant"))),"—") -> Compliant | H13: =IFERROR(IF(G13="Breached","Critical",IF(G13="Near Breach","Medium",IF(G13="Compliant","Low","—"))),"—") -> Low | I13: YBL SL 29-Dec-2025 | LTD/EBITDA ≤ 4.00x | J13: SL ✓ | K13: Annual | L13: FY29 (post-COD) | M13: 13
B14: LTD / Equity (consortium) | C14: <= | D14: 2 | E14: =IFERROR(INDEX('FY29 Covenant Compliance (TEV)'!F:F,MATCH(M14,'FY29 Covenant Compliance (TEV)'!A:A,0)),"—") -> 1.0922542 | F14: =IFERROR(IF(C14=">=",E14-D14,D14-E14),"—") -> 0.90774579 | G14: =IFERROR(IF(ISTEXT(E14),"Pending Input",IF(F14<0,"Breached",IF(F14<ABS(D14)*0.05,"Near Breach","Compliant"))),"—") -> Compliant | H14: =IFERROR(IF(G14="Breached","Critical",IF(G14="Near Breach","Medium",IF(G14="Compliant","Low","—"))),"—") -> Low | I14: YBL SL 29-Dec-2025 | LTD/Equity ≤ 2.00x | J14: SL ✓ | K14: Annual | L14: FY29 (post-COD) | M14: 14
B15: Cash Sweep Trigger (DSCR) | C15: >= | D15: 1.5 | E15: =IFERROR(INDEX('FY29 Covenant Compliance (TEV)'!F:F,MATCH(M15,'FY29 Covenant Compliance (TEV)'!A:A,0)),"—") -> 1.8008829 | F15: =IFERROR(IF(C15=">=",E15-D15,D15-E15),"—") -> 0.30088295 | G15: =IFERROR(IF(ISTEXT(E15),"Pending Input",IF(F15<0,"Breached",IF(F15<ABS(D15)*0.05,"Near Breach","Compliant"))),"—") -> Compliant | H15: =IFERROR(IF(G15="Breached","Critical",IF(G15="Near Breach","Medium",IF(G15="Compliant","Low","—"))),"—") -> Low | I15: YBL SL 29-Dec-2025 | Cash Sweep: DSCR > 1.5x triggers ₹75 Cr/yr sweep from 01-Apr-2028 | J15: SL ✓ | K15: 12-mo rolling | L15: 01-Apr-2028 (2yr post-COD) | M15: 15
A16: IDFC First Bank | B16: DSCR (IDFC-specific) | C16: >= | D16: 1.25 | E16: =IFERROR(INDEX('FY29 Covenant Compliance (TEV)'!F:F,MATCH(M16,'FY29 Covenant Compliance (TEV)'!A:A,0)),"—") -> 2.0479877 | F16: =IFERROR(IF(C16=">=",E16-D16,D16-E16),"—") -> 0.79798767 | G16: =IFERROR(IF(ISTEXT(E16),"Pending Input",IF(F16<0,"Breached",IF(F16<ABS(D16)*0.05,"Near Breach","Compliant"))),"—") -> Compliant | H16: =IFERROR(IF(G16="Breached","Critical",IF(G16="Near Breach","Medium",IF(G16="Compliant","Low","—"))),"—") -> Low | I16: IDFC SL 09-Jan-2026 | DSCR ≥ 1.25x — IDFC-specific formula; first test FY27 (2yr earlier) — FLAG | J16: SL ✓ | K16: Annual | L16: FY27 (2yr earlier — FLAG) | M16: 16
B17: FACR (consortium) | C17: >= | D17: 1.2 | E17: =IFERROR(INDEX('FY29 Covenant Compliance (TEV)'!F:F,MATCH(M17,'FY29 Covenant Compliance (TEV)'!A:A,0)),"—") -> 1.5100186 | F17: =IFERROR(IF(C17=">=",E17-D17,D17-E17),"—") -> 0.31001863 | G17: =IFERROR(IF(ISTEXT(E17),"Pending Input",IF(F17<0,"Breached",IF(F17<ABS(D17)*0.05,"Near Breach","Compliant"))),"—") -> Compliant | H17: =IFERROR(IF(G17="Breached","Critical",IF(G17="Near Breach","Medium",IF(G17="Compliant","Low","—"))),"—") -> Low | I17: IDFC SL 09-Jan-2026 | FACR ≥ 1.20x | First test FY27 | J17: SL ✓ | K17: Annual | L17: FY27 | M17: 17
B18: ISCR (consortium) | C18: >= | D18: 2 | E18: =IFERROR(INDEX('FY29 Covenant Compliance (TEV)'!F:F,MATCH(M18,'FY29 Covenant Compliance (TEV)'!A:A,0)),"—") -> 3.6548828 | F18: =IFERROR(IF(C18=">=",E18-D18,D18-E18),"—") -> 1.6548828 | G18: =IFERROR(IF(ISTEXT(E18),"Pending Input",IF(F18<0,"Breached",IF(F18<ABS(D18)*0.05,"Near Breach","Compliant"))),"—") -> Compliant | H18: =IFERROR(IF(G18="Breached","Critical",IF(G18="Near Breach","Medium",IF(G18="Compliant","Low","—"))),"—") -> Low | I18: IDFC SL 09-Jan-2026 | ISCR ≥ 2.00x | First test FY27 | J18: SL ✓ | K18: Annual | L18: FY27 | M18: 18
B19: LTD / EBITDA (consortium) | C19: <= | D19: 4 | E19: =IFERROR(INDEX('FY29 Covenant Compliance (TEV)'!F:F,MATCH(M19,'FY29 Covenant Compliance (TEV)'!A:A,0)),"—") -> 2.4944117 | F19: =IFERROR(IF(C19=">=",E19-D19,D19-E19),"—") -> 1.5055883 | G19: =IFERROR(IF(ISTEXT(E19),"Pending Input",IF(F19<0,"Breached",IF(F19<ABS(D19)*0.05,"Near Breach","Compliant"))),"—") -> Compliant | H19: =IFERROR(IF(G19="Breached","Critical",IF(G19="Near Breach","Medium",IF(G19="Compliant","Low","—"))),"—") -> Low | I19: IDFC SL 09-Jan-2026 | LTD/EBITDA ≤ 4.00x | First test FY27 | J19: SL ✓ | K19: Annual | L19: FY27 | M19: 19
B20: LTD / Equity (consortium) | C20: <= | D20: 2 | E20: =IFERROR(INDEX('FY29 Covenant Compliance (TEV)'!F:F,MATCH(M20,'FY29 Covenant Compliance (TEV)'!A:A,0)),"—") -> 1.0922542 | F20: =IFERROR(IF(C20=">=",E20-D20,D20-E20),"—") -> 0.90774579 | G20: =IFERROR(IF(ISTEXT(E20),"Pending Input",IF(F20<0,"Breached",IF(F20<ABS(D20)*0.05,"Near Breach","Compliant"))),"—") -> Compliant | H20: =IFERROR(IF(G20="Breached","Critical",IF(G20="Near Breach","Medium",IF(G20="Compliant","Low","—"))),"—") -> Low | I20: IDFC SL 09-Jan-2026 | LTD/Equity ≤ 2.00x | First test FY27 | J20: SL ✓ | K20: Annual | L20: FY27 | M20: 20
B21: Quasi Equity Cap (Cr) | C21: <= | D21: 337.5 | E21: =IFERROR(INDEX('FY29 Covenant Compliance (TEV)'!F:F,MATCH(M21,'FY29 Covenant Compliance (TEV)'!A:A,0)),"—") -> 0 | F21: =IFERROR(IF(C21=">=",E21-D21,D21-E21),"—") -> 337.5 | G21: =IFERROR(IF(ISTEXT(E21),"Pending Input",IF(F21<0,"Breached",IF(F21<ABS(D21)*0.05,"Near Breach","Compliant"))),"—") -> Compliant | H21: =IFERROR(IF(G21="Breached","Critical",IF(G21="Near Breach","Medium",IF(G21="Compliant","Low","—"))),"—") -> Low | I21: IDFC SL 09-Jan-2026 | Quasi-Equity Cap ₹337.5 Cr. Actual ₹856.76 Cr (Audit Note 16+18: Jindal Coke ₹28.15 Cr + JSL ₹701.61 Cr + Virtuous ₹127.00 Cr). ICDs NOT formally subordinated — CONFIRM with IDFC whether bank applies equity-only test. | J21: MP ⚠ | K21: Continuous monitoring | L21: Ongoing from disbursement | M21: 21
A22: ICICI Bank (TL) | B22: DSCR (consortium) | C22: >= | D22: 1.25 | E22: =IFERROR(INDEX('FY29 Covenant Compliance (TEV)'!F:F,MATCH(M22,'FY29 Covenant Compliance (TEV)'!A:A,0)),"—") -> 1.8008829 | F22: =IFERROR(IF(C22=">=",E22-D22,D22-E22),"—") -> 0.55088295 | G22: =IFERROR(IF(ISTEXT(E22),"Pending Input",IF(F22<0,"Breached",IF(F22<ABS(D22)*0.05,"Near Breach","Compliant"))),"—") -> Compliant | H22: =IFERROR(IF(G22="Breached","Critical",IF(G22="Near Breach","Medium",IF(G22="Compliant","Low","—"))),"—") -> Low | I22: ICICI TL CAL 27-Mar-2026 | DSCR ≥ 1.25x | J22: SL ✓ | K22: Annual | L22: FY29 (within 120d of FY-end) | M22: 22
B23: FACR (consortium) | C23: >= | D23: 1.2 | E23: =IFERROR(INDEX('FY29 Covenant Compliance (TEV)'!F:F,MATCH(M23,'FY29 Covenant Compliance (TEV)'!A:A,0)),"—") -> 1.5100186 | F23: =IFERROR(IF(C23=">=",E23-D23,D23-E23),"—") -> 0.31001863 | G23: =IFERROR(IF(ISTEXT(E23),"Pending Input",IF(F23<0,"Breached",IF(F23<ABS(D23)*0.05,"Near Breach","Compliant"))),"—") -> Compliant | H23: =IFERROR(IF(G23="Breached","Critical",IF(G23="Near Breach","Medium",IF(G23="Compliant","Low","—"))),"—") -> Low | I23: ICICI TL CAL 27-Mar-2026 | FACR ≥ 1.20x | J23: SL ✓ | K23: Annual | L23: FY29 | M23: 23
B24: ISCR (consortium) | C24: >= | D24: 2 | E24: =IFERROR(INDEX('FY29 Covenant Compliance (TEV)'!F:F,MATCH(M24,'FY29 Covenant Compliance (TEV)'!A:A,0)),"—") -> 3.6548828 | F24: =IFERROR(IF(C24=">=",E24-D24,D24-E24),"—") -> 1.6548828 | G24: =IFERROR(IF(ISTEXT(E24),"Pending Input",IF(F24<0,"Breached",IF(F24<ABS(D24)*0.05,"Near Breach","Compliant"))),"—") -> Compliant | H24: =IFERROR(IF(G24="Breached","Critical",IF(G24="Near Breach","Medium",IF(G24="Compliant","Low","—"))),"—") -> Low | I24: ICICI TL CAL 27-Mar-2026 | ISCR ≥ 2.00x | J24: SL ✓ | K24: Annual | L24: FY29 | M24: 24
B25: LTD / EBITDA (consortium) | C25: <= | D25: 4 | E25: =IFERROR(INDEX('FY29 Covenant Compliance (TEV)'!F:F,MATCH(M25,'FY29 Covenant Compliance (TEV)'!A:A,0)),"—") -> 2.4944117 | F25: =IFERROR(IF(C25=">=",E25-D25,D25-E25),"—") -> 1.5055883 | G25: =IFERROR(IF(ISTEXT(E25),"Pending Input",IF(F25<0,"Breached",IF(F25<ABS(D25)*0.05,"Near Breach","Compliant"))),"—") -> Compliant | H25: =IFERROR(IF(G25="Breached","Critical",IF(G25="Near Breach","Medium",IF(G25="Compliant","Low","—"))),"—") -> Low | I25: ICICI TL CAL 27-Mar-2026 | LTD/EBITDA ≤ 4.00x | J25: SL ✓ | K25: Annual | L25: FY29 | M25: 25
B26: LTD / Equity (consortium) | C26: <= | D26: 2 | E26: =IFERROR(INDEX('FY29 Covenant Compliance (TEV)'!F:F,MATCH(M26,'FY29 Covenant Compliance (TEV)'!A:A,0)),"—") -> 1.0922542 | F26: =IFERROR(IF(C26=">=",E26-D26,D26-E26),"—") -> 0.90774579 | G26: =IFERROR(IF(ISTEXT(E26),"Pending Input",IF(F26<0,"Breached",IF(F26<ABS(D26)*0.05,"Near Breach","Compliant"))),"—") -> Compliant | H26: =IFERROR(IF(G26="Breached","Critical",IF(G26="Near Breach","Medium",IF(G26="Compliant","Low","—"))),"—") -> Low | I26: ICICI TL CAL 27-Mar-2026 | LTD/Equity ≤ 2.00x | J26: SL ✓ | K26: Annual | L26: FY29 | M26: 26
A27: RBL Bank | B27: Min Promoter Contribution (Cr) | C27: >= | D27: 1363 | E27: =IFERROR(INDEX('FY29 Covenant Compliance (TEV)'!F:F,MATCH(M27,'FY29 Covenant Compliance (TEV)'!A:A,0)),"—") -> 2186.35 | F27: =IFERROR(IF(C27=">=",E27-D27,D27-E27),"—") -> 823.35 | G27: =IFERROR(IF(ISTEXT(E27),"Pending Input",IF(F27<0,"Breached",IF(F27<ABS(D27)*0.05,"Near Breach","Compliant"))),"—") -> Compliant | H27: =IFERROR(IF(G27="Breached","Critical",IF(G27="Near Breach","Medium",IF(G27="Compliant","Low","—"))),"—") -> Low | I27: RBL SL 13-Nov-2025 | Min ₹1,363 Cr promoter contribution. Actual ₹1,850.21 Cr (equity ₹993.45 Cr + ICDs ₹856.76 Cr). CAVEAT: equity-only = ₹993.45 Cr < threshold → potential breach. CONFIRM with RBL. | J27: MP ⚠ | K27: At disbursement & periodic | L27: Within 180d of disbursement | M27: 27
B28: JSL FMV Unencumbered / Total Debt | C28: >= | D28: 2.5 | E28: =IFERROR(INDEX('FY29 Covenant Compliance (TEV)'!F:F,MATCH(M28,'FY29 Covenant Compliance (TEV)'!A:A,0)),"—") -> 11.381328 | F28: =IFERROR(IF(C28=">=",E28-D28,D28-E28),"—") -> 8.881328 | G28: =IFERROR(IF(ISTEXT(E28),"Pending Input",IF(F28<0,"Breached",IF(F28<ABS(D28)*0.05,"Near Breach","Compliant"))),"—") -> Compliant | H28: =IFERROR(IF(G28="Breached","Critical",IF(G28="Near Breach","Medium",IF(G28="Compliant","Low","—"))),"—") -> Low | I28: RBL SL 13-Nov-2025 | JSL FMV (unencumbered) ÷ Total RBL debt ≥ 2.5x. Requires live NSE data. | J28: SL ✓ | K28: Continuous monitoring | L28: Ongoing from disbursement | M28: 28
B29: Min External Rating | C29: >= | D29: 10 | E29: =IFERROR(INDEX('FY29 Covenant Compliance (TEV)'!F:F,MATCH(M29,'FY29 Covenant Compliance (TEV)'!A:A,0)),"—") -> 14 | F29: =IFERROR(IF(C29=">=",E29-D29,D29-E29),"—") -> 4 | G29: =IFERROR(IF(ISTEXT(E29),"Pending Input",IF(F29<0,"Breached",IF(F29<ABS(D29)*0.05,"Near Breach","Compliant"))),"—") -> Compliant | H29: =IFERROR(IF(G29="Breached","Critical",IF(G29="Near Breach","Medium",IF(G29="Compliant","Low","—"))),"—") -> Low | I29: RBL SL p.11 | Rating ≥ BBB (= numeric 10). NOT BBB+ (=12). Within 180d of disbursement. | J29: SL ✓ | K29: On rating event | L29: Within 180d of disbursement | M29: 29
A30: ICICI Bank | B30: Total Debt / EBITDA (WC) | C30: <= | D30: 4 | E30: =IFERROR(INDEX('FY29 Covenant Compliance (TEV)'!F:F,MATCH(M30,'FY29 Covenant Compliance (TEV)'!A:A,0)),"—") -> 2.8147719 | F30: =IFERROR(IF(C30=">=",E30-D30,D30-E30),"—") -> 1.1852281 | G30: =IFERROR(IF(ISTEXT(E30),"Pending Input",IF(F30<0,"Breached",IF(F30<ABS(D30)*0.05,"Near Breach","Compliant"))),"—") -> Compliant | H30: =IFERROR(IF(G30="Breached","Critical",IF(G30="Near Breach","Medium",IF(G30="Compliant","Low","—"))),"—") -> Low | I30: ICICI WC CAL 12-Feb-2026 | Total Debt/EBITDA ≤ 4.00x | J30: SL ✓ | K30: Annual / on review | L30: Annual review 03-Feb-2027 | M30: 30
B31: TOL / TNW (WC) | C31: <= | D31: 2.5 | E31: =IFERROR(INDEX('FY29 Covenant Compliance (TEV)'!F:F,MATCH(M31,'FY29 Covenant Compliance (TEV)'!A:A,0)),"—") -> 1.7216136 | F31: =IFERROR(IF(C31=">=",E31-D31,D31-E31),"—") -> 0.77838635 | G31: =IFERROR(IF(ISTEXT(E31),"Pending Input",IF(F31<0,"Breached",IF(F31<ABS(D31)*0.05,"Near Breach","Compliant"))),"—") -> Compliant | H31: =IFERROR(IF(G31="Breached","Critical",IF(G31="Near Breach","Medium",IF(G31="Compliant","Low","—"))),"—") -> Low | I31: ICICI WC CAL 12-Feb-2026 | TOL/TNW ≤ 2.50x | J31: SL ✓ | K31: Annual / on review | L31: Annual review 03-Feb-2027 | M31: 31
B32: Current Ratio (WC) | C32: >= | D32: 1.1 | E32: =IFERROR(INDEX('FY29 Covenant Compliance (TEV)'!F:F,MATCH(M32,'FY29 Covenant Compliance (TEV)'!A:A,0)),"—") -> 1.8878634 | F32: =IFERROR(IF(C32=">=",E32-D32,D32-E32),"—") -> 0.78786337 | G32: =IFERROR(IF(ISTEXT(E32),"Pending Input",IF(F32<0,"Breached",IF(F32<ABS(D32)*0.05,"Near Breach","Compliant"))),"—") -> Compliant | H32: =IFERROR(IF(G32="Breached","Critical",IF(G32="Near Breach","Medium",IF(G32="Compliant","Low","—"))),"—") -> Low | I32: ICICI WC CAL 12-Feb-2026 | Current Ratio ≥ 1.10x | J32: SL ✓ | K32: Annual / on review | L32: Annual review 03-Feb-2027 | M32: 32
B33: External Rating (WC) | C33: >= | D33: 14 | E33: =IFERROR(INDEX('FY29 Covenant Compliance (TEV)'!F:F,MATCH(M33,'FY29 Covenant Compliance (TEV)'!A:A,0)),"—") -> 14 | F33: =IFERROR(IF(C33=">=",E33-D33,D33-E33),"—") -> 0 | G33: =IFERROR(IF(ISTEXT(E33),"Pending Input",IF(F33<0,"Breached",IF(F33<ABS(D33)*0.05,"Near Breach","Compliant"))),"—") -> Near Breach | H33: =IFERROR(IF(G33="Breached","Critical",IF(G33="Near Breach","Medium",IF(G33="Compliant","Low","—"))),"—") -> Medium | I33: ICICI WC CAL 12-Feb-2026 | Rating ≥ A- (= numeric 14). At threshold — Near Breach. Upgrade required to clear. | J33: SL ✓ | K33: On rating event | L33: Annual review 03-Feb-2027 | M33: 33
A34: HDFC Bank | B34: JSL FMV / Total Debt Cover | C34: >= | D34: 2.5 | E34: =IFERROR(INDEX('FY29 Covenant Compliance (TEV)'!F:F,MATCH(M34,'FY29 Covenant Compliance (TEV)'!A:A,0)),"—") -> 11.381328 | F34: =IFERROR(IF(C34=">=",E34-D34,D34-E34),"—") -> 8.881328 | G34: =IFERROR(IF(ISTEXT(E34),"Pending Input",IF(F34<0,"Breached",IF(F34<ABS(D34)*0.05,"Near Breach","Compliant"))),"—") -> Compliant | H34: =IFERROR(IF(G34="Breached","Critical",IF(G34="Near Breach","Medium",IF(G34="Compliant","Low","—"))),"—") -> Low | I34: HDFC 26-Mar-2026 | JSL FMV ÷ Total HDFC debt ≥ 2.5x. Requires live NSE data. ⚠ F-15: covenant not confirmed in offer letter — Treasury to verify. | J34: SL ✓ | K34: Continuous monitoring | L34: Ongoing from disbursement | M34: 35
B35: DSCR (consortium) | C35: >= | D35: 1.25 | E35: =IFERROR(INDEX('FY29 Covenant Compliance (TEV)'!F:F,MATCH(M35,'FY29 Covenant Compliance (TEV)'!A:A,0)),"—") -> 1.8008829 | F35: =IFERROR(IF(C35=">=",E35-D35,D35-E35),"—") -> 0.55088295 | G35: =IFERROR(IF(ISTEXT(E35),"Pending Input",IF(F35<0,"Breached",IF(F35<ABS(D35)*0.05,"Near Breach","Compliant"))),"—") -> Compliant | H35: =IFERROR(IF(G35="Breached","Critical",IF(G35="Near Breach","Medium",IF(G35="Compliant","Low","—"))),"—") -> Low | I35: HDFC 26-Mar-2026 | DSCR ≥ 1.25x | J35: SL ✓ | K35: Annual | L35: FY29 (post-COD) | M35: 36
B36: FACR (consortium) | C36: >= | D36: 1.2 | E36: =IFERROR(INDEX('FY29 Covenant Compliance (TEV)'!F:F,MATCH(M36,'FY29 Covenant Compliance (TEV)'!A:A,0)),"—") -> 1.5100186 | F36: =IFERROR(IF(C36=">=",E36-D36,D36-E36),"—") -> 0.31001863 | G36: =IFERROR(IF(ISTEXT(E36),"Pending Input",IF(F36<0,"Breached",IF(F36<ABS(D36)*0.05,"Near Breach","Compliant"))),"—") -> Compliant | H36: =IFERROR(IF(G36="Breached","Critical",IF(G36="Near Breach","Medium",IF(G36="Compliant","Low","—"))),"—") -> Low | I36: HDFC 26-Mar-2026 | FACR ≥ 1.20x | J36: SL ✓ | K36: Annual | L36: FY29 (post-COD) | M36: 37
B37: ISCR (consortium) | C37: >= | D37: 2 | E37: =IFERROR(INDEX('FY29 Covenant Compliance (TEV)'!F:F,MATCH(M37,'FY29 Covenant Compliance (TEV)'!A:A,0)),"—") -> 3.6548828 | F37: =IFERROR(IF(C37=">=",E37-D37,D37-E37),"—") -> 1.6548828 | G37: =IFERROR(IF(ISTEXT(E37),"Pending Input",IF(F37<0,"Breached",IF(F37<ABS(D37)*0.05,"Near Breach","Compliant"))),"—") -> Compliant | H37: =IFERROR(IF(G37="Breached","Critical",IF(G37="Near Breach","Medium",IF(G37="Compliant","Low","—"))),"—") -> Low | I37: HDFC 26-Mar-2026 | ISCR ≥ 2.00x | J37: SL ✓ | K37: Annual | L37: FY29 (post-COD) | M37: 38
B38: LTD / EBITDA (consortium) | C38: <= | D38: 4 | E38: =IFERROR(INDEX('FY29 Covenant Compliance (TEV)'!F:F,MATCH(M38,'FY29 Covenant Compliance (TEV)'!A:A,0)),"—") -> 2.4944117 | F38: =IFERROR(IF(C38=">=",E38-D38,D38-E38),"—") -> 1.5055883 | G38: =IFERROR(IF(ISTEXT(E38),"Pending Input",IF(F38<0,"Breached",IF(F38<ABS(D38)*0.05,"Near Breach","Compliant"))),"—") -> Compliant | H38: =IFERROR(IF(G38="Breached","Critical",IF(G38="Near Breach","Medium",IF(G38="Compliant","Low","—"))),"—") -> Low | I38: HDFC 26-Mar-2026 | LTD/EBITDA ≤ 4.00x | J38: SL ✓ | K38: Annual | L38: FY29 (post-COD) | M38: 39
B39: LTD / Equity (consortium) | C39: <= | D39: 2 | E39: =IFERROR(INDEX('FY29 Covenant Compliance (TEV)'!F:F,MATCH(M39,'FY29 Covenant Compliance (TEV)'!A:A,0)),"—") -> 1.0922542 | F39: =IFERROR(IF(C39=">=",E39-D39,D39-E39),"—") -> 0.90774579 | G39: =IFERROR(IF(ISTEXT(E39),"Pending Input",IF(F39<0,"Breached",IF(F39<ABS(D39)*0.05,"Near Breach","Compliant"))),"—") -> Compliant | H39: =IFERROR(IF(G39="Breached","Critical",IF(G39="Near Breach","Medium",IF(G39="Compliant","Low","—"))),"—") -> Low | I39: HDFC 26-Mar-2026 | LTD/Equity ≤ 2.00x | J39: SL ✓ | K39: Annual | L39: FY29 (post-COD) | M39: 40
B40: Total Debt / EBITDA | C40: <= | D40: 4.25 | E40: =IFERROR(INDEX('FY29 Covenant Compliance (TEV)'!F:F,MATCH(M40,'FY29 Covenant Compliance (TEV)'!A:A,0)),"—") -> 2.8147719 | F40: =IFERROR(IF(C40=">=",E40-D40,D40-E40),"—") -> 1.4352281 | G40: =IFERROR(IF(ISTEXT(E40),"Pending Input",IF(F40<0,"Breached",IF(F40<ABS(D40)*0.05,"Near Breach","Compliant"))),"—") -> Compliant | H40: =IFERROR(IF(G40="Breached","Critical",IF(G40="Near Breach","Medium",IF(G40="Compliant","Low","—"))),"—") -> Low | I40: HDFC 26-Mar-2026 | Total Debt/EBITDA ≤ 4.25x | J40: SL ✓ | K40: Annual | L40: FY29 (post-COD) | M40: 41
...

Sheet Lender Summary
A1: LENDER SUMMARY — Multi-Bucket Debt Profile
A2: Sanctioned Debt = Bucket 1 (FB Mains) + Bucket 2 (NFB Mains) | Adjusted Consortium = Sanctioned − ICICI TL takeover (₹840 Cr) | Bucket 3 (FD-Backed) and Bucket 4 (Uncommitted) tracked separately.
A4: A. SANCTIONED DEBT — Bucket 1 (FB Mains) + Bucket 2 (NFB Mains)
A5: Lender | B5: FB Mains (₹ Cr) | C5: NFB Mains (₹ Cr) | D5: Sanctioned (₹ Cr) | E5: % of Total | F5: Facilities (B1+B2) | G5: NFB Contingent (₹ Cr)
A6: UBI | B6: =SUMIFS('Facility Master'!$K:$K, 'Facility Master'!$B:$B, $A6, 'Facility Master'!$H:$H, 1) -> 1361 | C6: =SUMIFS('Facility Master'!$K:$K, 'Facility Master'!$B:$B, $A6, 'Facility Master'!$H:$H, 2) -> 0 | D6: =B6+C6 -> 1361 | E6: =D6/D$15 -> 0.29168453 | F6: =COUNTIFS('Facility Master'!$B:$B, $A6, 'Facility Master'!$H:$H, ">=1", 'Facility Master'!$H:$H, "<=2") -> 2 | G6: =SUMIFS('Facility Master'!$K:$K, 'Facility Master'!$B:$B, $A6, 'Facility Master'!$H:$H, 2) + SUMIFS('Facility Master'!$K:$K, 'Facility Master'!$B:$B, $A6, 'Facility Master'!$AG:$AG, TRUE()) -> 750
A7: Indian Bank | B7: =SUMIFS('Facility Master'!$K:$K, 'Facility Master'!$B:$B, $A7, 'Facility Master'!$H:$H, 1) -> 235 | C7: =SUMIFS('Facility Master'!$K:$K, 'Facility Master'!$B:$B, $A7, 'Facility Master'!$H:$H, 2) -> 0 | D7: =B7+C7 -> 235 | E7: =D7/D$15 -> 0.050364338 | F7: =COUNTIFS('Facility Master'!$B:$B, $A7, 'Facility Master'!$H:$H, ">=1", 'Facility Master'!$H:$H, "<=2") -> 1 | G7: =SUMIFS('Facility Master'!$K:$K, 'Facility Master'!$B:$B, $A7, 'Facility Master'!$H:$H, 2) + SUMIFS('Facility Master'!$K:$K, 'Facility Master'!$B:$B, $A7, 'Facility Master'!$AG:$AG, TRUE()) -> 0
A8: RBL Bank | B8: =SUMIFS('Facility Master'!$K:$K, 'Facility Master'!$B:$B, $A8, 'Facility Master'!$H:$H, 1) -> 200 | C8: =SUMIFS('Facility Master'!$K:$K, 'Facility Master'!$B:$B, $A8, 'Facility Master'!$H:$H, 2) -> 0 | D8: =B8+C8 -> 200 | E8: =D8/D$15 -> 0.042863266 | F8: =COUNTIFS('Facility Master'!$B:$B, $A8, 'Facility Master'!$H:$H, ">=1", 'Facility Master'!$H:$H, "<=2") -> 1 | G8: =SUMIFS('Facility Master'!$K:$K, 'Facility Master'!$B:$B, $A8, 'Facility Master'!$H:$H, 2) + SUMIFS('Facility Master'!$K:$K, 'Facility Master'!$B:$B, $A8, 'Facility Master'!$AG:$AG, TRUE()) -> 200
A9: YES Bank | B9: =SUMIFS('Facility Master'!$K:$K, 'Facility Master'!$B:$B, $A9, 'Facility Master'!$H:$H, 1) -> 650 | C9: =SUMIFS('Facility Master'!$K:$K, 'Facility Master'!$B:$B, $A9, 'Facility Master'!$H:$H, 2) -> 0 | D9: =B9+C9 -> 650 | E9: =D9/D$15 -> 0.13930562 | F9: =COUNTIFS('Facility Master'!$B:$B, $A9, 'Facility Master'!$H:$H, ">=1", 'Facility Master'!$H:$H, "<=2") -> 1 | G9: =SUMIFS('Facility Master'!$K:$K, 'Facility Master'!$B:$B, $A9, 'Facility Master'!$H:$H, 2) + SUMIFS('Facility Master'!$K:$K, 'Facility Master'!$B:$B, $A9, 'Facility Master'!$AG:$AG, TRUE()) -> 100
A10: IDFC First Bank | B10: =SUMIFS('Facility Master'!$K:$K, 'Facility Master'!$B:$B, $A10, 'Facility Master'!$H:$H, 1) -> 530 | C10: =SUMIFS('Facility Master'!$K:$K, 'Facility Master'!$B:$B, $A10, 'Facility Master'!$H:$H, 2) -> 0 | D10: =B10+C10 -> 530 | E10: =D10/D$15 -> 0.11358766 | F10: =COUNTIFS('Facility Master'!$B:$B, $A10, 'Facility Master'!$H:$H, ">=1", 'Facility Master'!$H:$H, "<=2") -> 1 | G10: =SUMIFS('Facility Master'!$K:$K, 'Facility Master'!$B:$B, $A10, 'Facility Master'!$H:$H, 2) + SUMIFS('Facility Master'!$K:$K, 'Facility Master'!$B:$B, $A10, 'Facility Master'!$AG:$AG, TRUE()) -> 400
A11: ICICI Bank | B11: =SUMIFS('Facility Master'!$K:$K, 'Facility Master'!$B:$B, $A11, 'Facility Master'!$H:$H, 1) -> 100 | C11: =SUMIFS('Facility Master'!$K:$K, 'Facility Master'!$B:$B, $A11, 'Facility Master'!$H:$H, 2) -> 300 | D11: =B11+C11 -> 400 | E11: =D11/D$15 -> 0.085726532 | F11: =COUNTIFS('Facility Master'!$B:$B, $A11, 'Facility Master'!$H:$H, ">=1", 'Facility Master'!$H:$H, "<=2") -> 2 | G11: =SUMIFS('Facility Master'!$K:$K, 'Facility Master'!$B:$B, $A11, 'Facility Master'!$H:$H, 2) + SUMIFS('Facility Master'!$K:$K, 'Facility Master'!$B:$B, $A11, 'Facility Master'!$AG:$AG, TRUE()) -> 300
A12: HSBC | B12: =SUMIFS('Facility Master'!$K:$K, 'Facility Master'!$B:$B, $A12, 'Facility Master'!$H:$H, 1) -> 200 | C12: =SUMIFS('Facility Master'!$K:$K, 'Facility Master'!$B:$B, $A12, 'Facility Master'!$H:$H, 2) -> 0 | D12: =B12+C12 -> 200 | E12: =D12/D$15 -> 0.042863266 | F12: =COUNTIFS('Facility Master'!$B:$B, $A12, 'Facility Master'!$H:$H, ">=1", 'Facility Master'!$H:$H, "<=2") -> 1 | G12: =SUMIFS('Facility Master'!$K:$K, 'Facility Master'!$B:$B, $A12, 'Facility Master'!$H:$H, 2) + SUMIFS('Facility Master'!$K:$K, 'Facility Master'!$B:$B, $A12, 'Facility Master'!$AG:$AG, TRUE()) -> 0
A13: HDFC Bank | B13: =SUMIFS('Facility Master'!$K:$K, 'Facility Master'!$B:$B, $A13, 'Facility Master'!$H:$H, 1) -> 0 | C13: =SUMIFS('Facility Master'!$K:$K, 'Facility Master'!$B:$B, $A13, 'Facility Master'!$H:$H, 2) -> 250 | D13: =B13+C13 -> 250 | E13: =D13/D$15 -> 0.053579083 | F13: =COUNTIFS('Facility Master'!$B:$B, $A13, 'Facility Master'!$H:$H, ">=1", 'Facility Master'!$H:$H, "<=2") -> 1 | G13: =SUMIFS('Facility Master'!$K:$K, 'Facility Master'!$B:$B, $A13, 'Facility Master'!$H:$H, 2) + SUMIFS('Facility Master'!$K:$K, 'Facility Master'!$B:$B, $A13, 'Facility Master'!$AG:$AG, TRUE()) -> 250
A14: ICICI Bank (TL) | B14: =SUMIFS('Facility Master'!$K:$K, 'Facility Master'!$B:$B, $A14, 'Facility Master'!$H:$H, 1) -> 840 | C14: =SUMIFS('Facility Master'!$K:$K, 'Facility Master'!$B:$B, $A14, 'Facility Master'!$H:$H, 2) -> 0 | D14: =B14+C14 -> 840 | E14: =D14/D$15 -> 0.18002572 | F14: =COUNTIFS('Facility Master'!$B:$B, $A14, 'Facility Master'!$H:$H, ">=1", 'Facility Master'!$H:$H, "<=2") -> 1 | G14: =SUMIFS('Facility Master'!$K:$K, 'Facility Master'!$B:$B, $A14, 'Facility Master'!$H:$H, 2) + SUMIFS('Facility Master'!$K:$K, 'Facility Master'!$B:$B, $A14, 'Facility Master'!$AG:$AG, TRUE()) -> 40
A15: Grand Total | B15: =SUM(B6:B14) -> 4116 | C15: =SUM(C6:C14) -> 550 | D15: =SUM(D6:D14) -> 4666 | E15: 1 | F15: =SUM(F6:F14) -> 11 | G15: =SUM(G6:G14) -> 2040
A16: ⚠ ICICI Bank (TL) ₹840 Cr is a takeover of existing consortium TL — netted out in Adjusted Consortium Debt. Specific take-out lender(s) not identified in the CAL.
A18: B. KEY KPIs — Dashboard Linkage
A19: KPI | B19: Amount (₹ Cr) | C19: Definition
A20: Sanctioned Debt (B1 + B2) | B20: =SUMIFS('Facility Master'!K:K,'Facility Master'!H:H,1)+SUMIFS('Facility Master'!K:K,'Facility Master'!H:H,2) -> 4666 | C20: Bucket 1 + Bucket 2 main parents — gross of ICICI TL takeover
A21: FB Mains Total (Bucket 1) | B21: =SUMIFS('Facility Master'!K:K,'Facility Master'!H:H,1) -> 4116 | C21: All fund-based main parent facilities
A22: NFB Mains Total (Bucket 2) | B22: =SUMIFS('Facility Master'!K:K,'Facility Master'!H:H,2) -> 550 | C22: All non-fund-based main parent facilities
A23: NFB Contingent Total | B23: =SUMIFS('Facility Master'!K:K,'Facility Master'!H:H,2)+SUMIFS('Facility Master'!K:K,'Facility Master'!AG:AG,TRUE()) -> 2040 | C23: B2 mains + NFB sub-limits within FB-Main parents
A24: FD-Backed Total (Bucket 3) | B24: =SUMIFS('Facility Master'!K:K,'Facility Master'!H:H,3) -> 150 | C24: Self-collateralised; economic exposure effectively nil
A25: Uncommitted Memo (Bucket 4) | B25: =SUMIFS('Facility Master'!K:K,'Facility Master'!H:H,4) -> 0 | C25: HSBC: ₹200 Cr sanctioned (post 20% haircut on ₹1,000 Cr face — see MP-13). Uncommitted on paper; treated as effective committed for modelling. Bank retains right to withdraw.
A26: Hedge Memo | B26: =SUMIFS('Facility Master'!K:K,'Facility Master'!H:H,"H") -> 75 | C26: UBI Forward Contract ₹75 Cr — outside all buckets
A27: ICICI TL Takeover (Adjustment) | B27: =SUMIFS('Facility Master'!K:K,'Facility Master'!AH:AH,TRUE(),'Facility Master'!H:H,1) -> 840 | C27: ICICI TL substitutes for existing consortium TL
A28: Adjusted Consortium Debt | B28: =B20-B27 -> 3826 | C28: Sanctioned − ICICI TL takeover = ₹4,666 − ₹840 Cr
A30: C. FD-BACKED (BUCKET 3) — Self-Collateralised
A31: Lender | B31: FD-Backed (₹ Cr) | C31: % Share
A32: RBL Bank | B32: 100 | C32: 0.667
A33: HDFC Bank | B33: 50 | C33: 0.333
A34: Grand Total | B34: 150 | C34: 1
A36: D. UNCOMMITTED MEMO (BUCKET 4) — nil after HSBC reclassification (see MP-13 / F-18)
A37: Lender | B37: Uncommitted (₹ Cr) | C37: Status / Note
A38: HSBC | B38: 0 | C38: Reclassified to Bucket 1 (Sanctioned/FB Mains) at ₹200 Cr post 20% haircut. See MP-13 / F-18.
A40: E. HEDGE MEMO — Outside All Buckets
A41: Lender | B41: Notional (₹ Cr) | C41: Status / Note
A42: UBI | B42: 75 | C42: UBI Forward Contract (memo only) — treatment ambiguous; tracked outside all buckets.

Sheet Facility Master
A1: FACILITY MASTER — JFL Debt Model (Single Source of Truth)
A2: Source: 9 JFL sanction letters | 44 facilities | All schedules aggregate from here via SUMIFS/INDEX-MATCH | Do not edit — update via sanction letters only
A3: IDENTIFICATION | G3: Flags | I3: Financial Structure | P3: PRICING | T3: REPAYMENT | X3: DATES | AC3: REFERENCE & NOTES | AG3: BUCKET FLAGS
A4: S.No | B4: Lender | C4: Facility | D4: Category | E4: Nature | F4: Sub-Limit Flag | G4: FD-Backed | H4: Bucket | I4: Currency | J4: Sanc Orig Ccy | K4: Sanc INR Cr | L4: Current O/S | M4: Eff O/S | N4: Util % | O4: Headroom | P4: Benchmark | Q4: Spread | R4: Eff Rate p.a. | S4: Rate Type | T4: Moratorium Mths | U4: Rep Frequency | V4: Tenor Mths | W4: No of Instals | X4: Drawdown Date | Y4: Rep Start Date | Z4: Maturity Date | AA4: Sanction Date | AB4: Validity Date | AC4: Purpose | AD4: Security Summary | AE4: Sanction Reference | AF4: Remarks | AG4: NFB Contingent Flag | AH4: Takeover Flag
A5: 1 | B5: UBI | C5: RTL-I (renewal) | D5: FB-Term | E5: Non-Revolving | F5: =FALSE() -> FALSE | G5: =FALSE() -> FALSE | H5: 1 | I5: INR | J5: 1125 | K5: =IFERROR(J5,0) -> 1125 | M5: =IFERROR(IF(D5="FB-Term",IF(A5=UBI_RTL1_SNo,UBI_RTL1_PrincOS,IF(A5=UBI_RTL2_SNo,UBI_RTL2_PrincOS,IF(A5=IB_TL_SNo,IB_TL_PrincOS,IF(A5=RBL_TL_SNo,RBL_TL_PrincOS,IF(A5=YBL_TL_SNo,YBL_TL_PrincOS,IF(A5=IDFC_TL_SNo,IDFC_TL_PrincOS,IF(A5=ICICI_TL_SNo,ICICI_TL_PrincOS,0))))))),IF(L5<>"",L5,IF(UseFullUtil,K5,0))),0) -> 1125 | N5: =IFERROR(M5/K5,0) -> 1 | O5: =IFERROR(K5-M5,0) -> 0 | P5: 1Y MCLR (UBI) | Q5: 0.005 | R5: =IFERROR(VLOOKUP(P5,'Instructions & Assumptions'!$A$14:$B$27,2,FALSE())+Q5,Q5) -> 0.094 | S5: Floating | T5: 48 | U5: Quarterly | V5: 192 | W5: 48 | X5: 45104 | Y5: 46568 | Z5: 50860 | AA5: 45920 | AB5: 50860 | AC5: Project capex — 2.0 MTPA Greenfield Steel Making at Kalinga Nagar | AD5: 1st p-p on FA (movable+immovable+leasehold 220.68 acres); 1st p-p on intangibles; 2nd p-p on CA; 1st p-p Escrow; Pledge 51% by OPJSTPL; OPJSTPL CG; JCL CG (till perfection); JSL DSU | AE5: UBI SL 20-Sep-2025, Ref LCBD-I:JFL:2025-26:1726 | AF5: Renewal of existing TL; 1Y MCLR 8.90% per UBI SL p.1 (RTL-I); Spread 0.50% -> effective 9.40% p.a. at present. Next MCLR reset 26-Jun-2026. (RTL-II uses 1Y MCLR 8.60% + 0.50% = 9.10%.) | AG5: =FALSE() -> FALSE | AH5: =FALSE() -> FALSE
A6: 2 | B6: UBI | C6: RTL-II (fresh) | D6: FB-Term | E6: Non-Revolving | F6: =FALSE() -> FALSE | G6: =FALSE() -> FALSE | H6: 1 | I6: INR | J6: 236 | K6: =IFERROR(J6,0) -> 236 | M6: =IFERROR(IF(D6="FB-Term",IF(A6=UBI_RTL1_SNo,UBI_RTL1_PrincOS,IF(A6=UBI_RTL2_SNo,UBI_RTL2_PrincOS,IF(A6=IB_TL_SNo,IB_TL_PrincOS,IF(A6=RBL_TL_SNo,RBL_TL_PrincOS,IF(A6=YBL_TL_SNo,YBL_TL_PrincOS,IF(A6=IDFC_TL_SNo,IDFC_TL_PrincOS,IF(A6=ICICI_TL_SNo,ICICI_TL_PrincOS,0))))))),IF(L6<>"",L6,IF(UseFullUtil,K6,0))),0) -> 236 | N6: =IFERROR(M6/K6,0) -> 1 | O6: =IFERROR(K6-M6,0) -> 0 | P6: 1Y MCLR (UBI) — RTL-II | Q6: 0.005 | R6: =IFERROR(VLOOKUP(P6,'Instructions & Assumptions'!$A$14:$B$27,2,FALSE())+Q6,Q6) -> 0.091 | S6: Floating | T6: 21 | U6: Quarterly | V6: 162 | W6: 48 | X6: 45920 | Y6: 46568 | Z6: 50860 | AA6: 45920 | AB6: 50860 | AC6: Project capex — fresh facility within UBI 20-Sep-2025 SL | AD6: 1st p-p on FA; 1st p-p on intangibles; 2nd p-p on CA; 1st p-p Escrow; Pledge 51% by OPJSTPL; OPJSTPL CG; JCL CG; JSL DSU | AE6: UBI SL 20-Sep-2025, Ref LCBD-I:JFL:2025-26:1726 | AF6: Fresh facility; 1Y MCLR 8.60% (reset basis); consortium-aligned 48 quarterly | AG6: =FALSE() -> FALSE | AH6: =FALSE() -> FALSE
A7: 3 | B7: UBI | C7: Letter of Credit (Capex LC/UPAS/SBLC) | D7: NFB | E7: Revolving | F7: =TRUE() -> TRUE | G7: =FALSE() -> FALSE | H7: 0 | I7: INR | J7: 750 | K7: =IFERROR(J7,0) -> 750 | M7: =IFERROR(IF(D7="FB-Term",IF(A7=UBI_RTL1_SNo,UBI_RTL1_PrincOS,IF(A7=UBI_RTL2_SNo,UBI_RTL2_PrincOS,IF(A7=IB_TL_SNo,IB_TL_PrincOS,IF(A7=RBL_TL_SNo,RBL_TL_PrincOS,IF(A7=YBL_TL_SNo,YBL_TL_PrincOS,IF(A7=IDFC_TL_SNo,IDFC_TL_PrincOS,IF(A7=ICICI_TL_SNo,ICICI_TL_PrincOS,0))))))),IF(L7<>"",L7,IF(UseFullUtil,K7,0))),0) -> 750 | N7: =IFERROR(M7/K7,0) -> 1 | O7: =IFERROR(K7-M7,0) -> 0 | P7: Fixed commission | Q7: 0.006 | R7: =IFERROR(VLOOKUP(P7,'Instructions & Assumptions'!$A$14:$B$27,2,FALSE())+Q7,Q7) -> 0.006 | S7: Fixed | T7: 0 | U7: On Maturity | V7: 12 | W7: 0 | X7: 45920 | Y7: =IFERROR(EDATE(X7,T7),"") -> 45920 | Z7: =IFERROR(EDATE(X7,V7),"") -> 46285 | AA7: 45920 | AB7: 46284 | AC7: NFB sub-limit; capex LC and UPAS issuance | AD7: Same as RTL primary (1st p-p on FA, 2nd on CA, Pledge 51%, OPJSTPL CG, JCL CG, JSL DSU) | AE7: UBI SL 20-Sep-2025, Ref LCBD-I:JFL:2025-26:1726 | AF7: 0.60% p.a. + GST commission; UBI branch SBLC; other-bank SBLC 0.85% | AG7: =TRUE() -> TRUE | AH7: =FALSE() -> FALSE
A8: 4 | B8: UBI | C8: Bank Guarantee | D8: NFB | E8: Revolving | F8: =TRUE() -> TRUE | G8: =FALSE() -> FALSE | H8: 0 | I8: INR | J8: 12.5 | K8: =IFERROR(J8,0) -> 12.5 | M8: =IFERROR(IF(D8="FB-Term",IF(A8=UBI_RTL1_SNo,UBI_RTL1_PrincOS,IF(A8=UBI_RTL2_SNo,UBI_RTL2_PrincOS,IF(A8=IB_TL_SNo,IB_TL_PrincOS,IF(A8=RBL_TL_SNo,RBL_TL_PrincOS,IF(A8=YBL_TL_SNo,YBL_TL_PrincOS,IF(A8=IDFC_TL_SNo,IDFC_TL_PrincOS,IF(A8=ICICI_TL_SNo,ICICI_TL_PrincOS,0))))))),IF(L8<>"",L8,IF(UseFullUtil,K8,0))),0) -> 12.5 | N8: =IFERROR(M8/K8,0) -> 1 | O8: =IFERROR(K8-M8,0) -> 0 | P8: Fixed commission | Q8: 0.006 | R8: =IFERROR(VLOOKUP(P8,'Instructions & Assumptions'!$A$14:$B$27,2,FALSE())+Q8,Q8) -> 0.006 | S8: Fixed | T8: 0 | U8: On Maturity | V8: 36 | W8: 0 | X8: 45920 | Y8: =IFERROR(EDATE(X8,T8),"") -> 45920 | Z8: =IFERROR(EDATE(X8,V8),"") -> 47016 | AA8: 45920 | AB8: 46284 | AC8: Performance/financial BG | AD8: Same as RTL primary | AE8: UBI SL 20-Sep-2025, Ref LCBD-I:JFL:2025-26:1726 | AF8: 0.60% p.a. + GST | AG8: =FALSE() -> FALSE | AH8: =FALSE() -> FALSE
A9: 5 | B9: UBI | C9: Forward Contract (credit equivalent) | D9: Hedge | E9: Revolving | F9: =FALSE() -> FALSE | G9: =FALSE() -> FALSE | H9: H | I9: INR | J9: 75 | K9: =IFERROR(J9,0) -> 75 | M9: =IFERROR(IF(D9="FB-Term",IF(A9=UBI_RTL1_SNo,UBI_RTL1_PrincOS,IF(A9=UBI_RTL2_SNo,UBI_RTL2_PrincOS,IF(A9=IB_TL_SNo,IB_TL_PrincOS,IF(A9=RBL_TL_SNo,RBL_TL_PrincOS,IF(A9=YBL_TL_SNo,YBL_TL_PrincOS,IF(A9=IDFC_TL_SNo,IDFC_TL_PrincOS,IF(A9=ICICI_TL_SNo,ICICI_TL_PrincOS,0))))))),IF(L9<>"",L9,IF(UseFullUtil,K9,0))),0) -> 75 | N9: =IFERROR(M9/K9,0) -> 1 | O9: =IFERROR(K9-M9,0) -> 0 | P9: N/A | Q9: 0 | R9: =IFERROR(VLOOKUP(P9,'Instructions & Assumptions'!$A$14:$B$27,2,FALSE())+Q9,Q9) -> 0 | S9: Fixed | T9: 0 | U9: On Settlement | V9: 12 | W9: 0 | X9: 45920 | Y9: =IFERROR(EDATE(X9,T9),"") -> 45920 | Z9: =IFERROR(EDATE(X9,V9),"") -> 46285 | AA9: 45920 | AB9: 46284 | AC9: Hedging exchange risk | AD9: Unsecured | AE9: UBI SL 20-Sep-2025, Ref LCBD-I:JFL:2025-26:1726 | AF9: MEMO ONLY. '^' superscript on UBI cover table with no footnote — treatment ambiguous; provisionally classified as hedge memo. Out of all buckets. | AG9: =FALSE() -> FALSE | AH9: =FALSE() -> FALSE
A10: 6 | B10: Indian Bank | C10: Term Loan (per amendment ticket) | D10: FB-Term | E10: Non-Revolving | F10: =FALSE() -> FALSE | G10: =FALSE() -> FALSE | H10: 1 | I10: INR | J10: 235 | K10: =IFERROR(J10,0) -> 235 | M10: =IFERROR(IF(D10="FB-Term",IF(A10=UBI_RTL1_SNo,UBI_RTL1_PrincOS,IF(A10=UBI_RTL2_SNo,UBI_RTL2_PrincOS,IF(A10=IB_TL_SNo,IB_TL_PrincOS,IF(A10=RBL_TL_SNo,RBL_TL_PrincOS,IF(A10=YBL_TL_SNo,YBL_TL_PrincOS,IF(A10=IDFC_TL_SNo,IDFC_TL_PrincOS,IF(A10=ICICI_TL_SNo,ICICI_TL_PrincOS,0))))))),IF(L10<>"",L10,IF(UseFullUtil,K10,0))),0) -> 235 | N10: =IFERROR(M10/K10,0) -> 1 | O10: =IFERROR(K10-M10,0) -> 0 | P10: 1Y MCLR (Indian Bank) | Q10: 0.005 | R10: =IFERROR(VLOOKUP(P10,'Instructions & Assumptions'!$A$14:$B$27,2,FALSE())+Q10,Q10) -> 0.094 | S10: Floating | T10: 50 | U10: Quarterly | V10: 192 | W10: 48 | X10: 44927 | Y10: 46477 | Z10: 50770 | AA10: 45926 | AB10: =Z10 -> 50770 | AC10: Project capex — long-dated consortium TL | AD10: Per original Indian Bank SL (NOT in file set). Presumed consortium-standard security. | AE10: Indian Bank Amendment Ticket 26-Sep-2025, Ref LCB/Del/JFL:2025-26 | AF10: Indian Bank: Loan ₹235 Cr DERIVED from repayment table totals (8Q × ₹2.9375 + 40Q × ₹5.2875 = ₹235 ✓). 12-yr tenor; 12-mo moratorium; graduated 1.25%/2.25% quarterly; per amendment ticket 26-Sep-2025. | AG10: =FALSE() -> FALSE | AH10: =FALSE() -> FALSE
A11: 7 | B11: RBL Bank | C11: Term Loan (12-month bullet bridge) | D11: FB-Term | E11: Non-Revolving | F11: =FALSE() -> FALSE | G11: =FALSE() -> FALSE | H11: 1 | I11: INR | J11: 200 | K11: =IFERROR(J11,0) -> 200 | M11: =IFERROR(IF(D11="FB-Term",IF(A11=UBI_RTL1_SNo,UBI_RTL1_PrincOS,IF(A11=UBI_RTL2_SNo,UBI_RTL2_PrincOS,IF(A11=IB_TL_SNo,IB_TL_PrincOS,IF(A11=RBL_TL_SNo,RBL_TL_PrincOS,IF(A11=YBL_TL_SNo,YBL_TL_PrincOS,IF(A11=IDFC_TL_SNo,IDFC_TL_PrincOS,IF(A11=ICICI_TL_SNo,ICICI_TL_PrincOS,0))))))),IF(L11<>"",L11,IF(UseFullUtil,K11,0))),0) -> 200 | N11: =IFERROR(M11/K11,0) -> 1 | O11: =IFERROR(K11-M11,0) -> 0 | P11: To be decided | Q11: 0 | R11: =IFERROR(VLOOKUP(P11,'Instructions & Assumptions'!$A$14:$B$27,2,FALSE())+Q11,Q11) -> 0.095 | S11: TBD | T11: 0 | U11: Bullet | V11: 12 | W11: 1 | X11: 45974 | Y11: 46339 | Z11: 46339 | AA11: 45974 | AB11: 46265 | AC11: Part-finance 2.0 MTPA capex + repay ICDs from JSL/Jindal Coke | AD11: Unconditional & Irrevocable CG from OPJSTPL; Shortfall Undertaking from JSL Ltd | AE11: RBL SL 13-Nov-2025, Ref CAD/DEL/0856/2025-26 | AF11: FLAG: Bridge facility — 12-month BULLET, NOT consortium amortising. Rate 'to be decided at disbursement' — FLAG. Min promoter contribution ₹1,363 Cr covenant. Min BBB rating within 180 days. | AG11: =FALSE() -> FALSE | AH11: =FALSE() -> FALSE
A12: 8 | B12: RBL Bank | C12: Letter of Credit (sub-limit of TL) | D12: NFB | E12: Revolving | F12: =TRUE() -> TRUE | G12: =FALSE() -> FALSE | H12: 0 | I12: INR | J12: 200 | K12: =IFERROR(J12,0) -> 200 | M12: =IFERROR(IF(D12="FB-Term",IF(A12=UBI_RTL1_SNo,UBI_RTL1_PrincOS,IF(A12=UBI_RTL2_SNo,UBI_RTL2_PrincOS,IF(A12=IB_TL_SNo,IB_TL_PrincOS,IF(A12=RBL_TL_SNo,RBL_TL_PrincOS,IF(A12=YBL_TL_SNo,YBL_TL_PrincOS,IF(A12=IDFC_TL_SNo,IDFC_TL_PrincOS,IF(A12=ICICI_TL_SNo,ICICI_TL_PrincOS,0))))))),IF(L12<>"",L12,IF(UseFullUtil,K12,0))),0) -> 200 | N12: =IFERROR(M12/K12,0) -> 1 | O12: =IFERROR(K12-M12,0) -> 0 | P12: Fixed commission | Q12: 0.005 | R12: =IFERROR(VLOOKUP(P12,'Instructions & Assumptions'!$A$14:$B$27,2,FALSE())+Q12,Q12) -> 0.005 | S12: Fixed | T12: 0 | U12: On Maturity | V12: 6 | W12: 0 | X12: 45974 | Y12: =IFERROR(EDATE(X12,T12),"") -> 45974 | Z12: =IFERROR(EDATE(X12,V12),"") -> 46155 | AA12: 45974 | AB12: 46265 | AC12: Procurement of raw material for testing/commissioning phase | AD12: Same as TL parent | AE12: RBL SL 13-Nov-2025, Ref CAD/DEL/0856/2025-26 | AF12: Sub-limit within ₹200 Cr TL; 0.50% p.a. commission; no LCs to sister/group companies; 6 months max per LC | AG12: =TRUE() -> TRUE | AH12: =FALSE() -> FALSE
A13: 9 | B13: RBL Bank | C13: FDOD (Overdraft against FD) | D13: FB-FDbacked | E13: Revolving | F13: =FALSE() -> FALSE | G13: =TRUE() -> TRUE | H13: 3 | I13: INR | J13: 100 | K13: =IFERROR(J13,0) -> 100 | M13: =IFERROR(IF(D13="FB-Term",IF(A13=UBI_RTL1_SNo,UBI_RTL1_PrincOS,IF(A13=UBI_RTL2_SNo,UBI_RTL2_PrincOS,IF(A13=IB_TL_SNo,IB_TL_PrincOS,IF(A13=RBL_TL_SNo,RBL_TL_PrincOS,IF(A13=YBL_TL_SNo,YBL_TL_PrincOS,IF(A13=IDFC_TL_SNo,IDFC_TL_PrincOS,IF(A13=ICICI_TL_SNo,ICICI_TL_PrincOS,0))))))),IF(L13<>"",L13,IF(UseFullUtil,K13,0))),0) -> 100 | N13: =IFERROR(M13/K13,0) -> 1 | O13: =IFERROR(K13-M13,0) -> 0 | P13: To be decided | Q13: 0 | R13: =IFERROR(VLOOKUP(P13,'Instructions & Assumptions'!$A$14:$B$27,2,FALSE())+Q13,Q13) -> 0.095 | S13: TBD | T13: 0 | U13: On Demand | V13: 12 | W13: 0 | X13: 45974 | Y13: =IFERROR(EDATE(X13,T13),"") -> 45974 | Z13: =IFERROR(EDATE(X13,V13),"") -> 46339 | AA13: 45974 | AB13: 46265 | AC13: Cash-flow mismatches | AD13: 100% lien on FD held by JFL/JSL/Jindal Coke/JUSL; up to 90% of FD value lien-marked | AE13: RBL SL 13-Nov-2025, Ref CAD/DEL/0856/2025-26 | AF13: FD-backed; economic exposure nil; rate TBD at disbursement — FLAG | AG13: =FALSE() -> FALSE | AH13: =FALSE() -> FALSE
